<?xml version="1.0" encoding="UTF-8"?>
<!-- Generated by org.testng.reporters.JUnitReportReporter -->
<testsuite hostname="DESKTOP-HB25A9N" failures="3" tests="13" name="org.rntgroup.CalcUnitTests.SinTest" time="0.007" errors="0" timestamp="2024-02-29T13:20:20 MSK" skipped="0">
  <testcase classname="org.rntgroup.CalcUnitTests.SinTest" name="unitSinTest" time="0.000"/>
  <testcase classname="org.rntgroup.CalcUnitTests.SinTest" name="unitSinTest" time="0.001"/>
  <testcase classname="org.rntgroup.CalcUnitTests.SinTest" name="unitSinTest" time="0.001">
    <failure message="Result is not correct! expected [0.0] but found [1.2246467991473532E-16]" type="java.lang.AssertionError">
      <![CDATA[java.lang.AssertionError: Result is not correct! expected [0.0] but found [1.2246467991473532E-16]
at org.testng.Assert.fail(Assert.java:111)
at org.testng.Assert.failNotEquals(Assert.java:1578)
at org.testng.Assert.assertEquals(Assert.java:728)
at org.rntgroup.CalcUnitTests.SinTest.unitSinTest(SinTest.java:31)
at java.base/jdk.internal.reflect.NativeMethodAccessorImpl.invoke0(Native Method)
at java.base/jdk.internal.reflect.NativeMethodAccessorImpl.invoke(NativeMethodAccessorImpl.java:77)
at java.base/jdk.internal.reflect.DelegatingMethodAccessorImpl.invoke(DelegatingMethodAccessorImpl.java:43)
at java.base/java.lang.reflect.Method.invoke(Method.java:568)
at org.testng.internal.invokers.MethodInvocationHelper.invokeMethod(MethodInvocationHelper.java:139)
at org.testng.internal.invokers.TestInvoker.invokeMethod(TestInvoker.java:664)
at org.testng.internal.invokers.TestInvoker.invokeTestMethod(TestInvoker.java:228)
at org.testng.internal.invokers.MethodRunner.runInSequence(MethodRunner.java:63)
at org.testng.internal.invokers.TestInvoker$MethodInvocationAgent.invoke(TestInvoker.java:961)
at org.testng.internal.invokers.TestInvoker.invokeTestMethods(TestInvoker.java:201)
at org.testng.internal.invokers.TestMethodWorker.invokeTestMethods(TestMethodWorker.java:148)
at org.testng.internal.invokers.TestMethodWorker.run(TestMethodWorker.java:128)
at java.base/java.util.concurrent.Executors$RunnableAdapter.call(Executors.java:539)
at java.base/java.util.concurrent.FutureTask.run(FutureTask.java:264)
at org.testng.internal.thread.graph.TestNGFutureTask.run(TestNGFutureTask.java:22)
at java.base/java.util.concurrent.ThreadPoolExecutor.runWorker(ThreadPoolExecutor.java:1136)
at java.base/java.util.concurrent.ThreadPoolExecutor$Worker.run(ThreadPoolExecutor.java:635)
at java.base/java.lang.Thread.run(Thread.java:840)
]]>
    </failure>
  </testcase> <!-- unitSinTest -->
  <testcase classname="org.rntgroup.CalcUnitTests.SinTest" name="unitSinOfInfinityTest" time="0.001">
    <failure message="Expected IllegalArgumentException to be thrown, but nothing was thrown" type="java.lang.AssertionError">
      <![CDATA[java.lang.AssertionError: Expected IllegalArgumentException to be thrown, but nothing was thrown
at org.testng.Assert.expectThrows(Assert.java:2460)
at org.testng.Assert.expectThrows(Assert.java:2425)
at org.testng.Assert.assertThrows(Assert.java:2391)
at org.rntgroup.CalcUnitTests.SinTest.unitSinOfInfinityTest(SinTest.java:36)
at java.base/jdk.internal.reflect.NativeMethodAccessorImpl.invoke0(Native Method)
at java.base/jdk.internal.reflect.NativeMethodAccessorImpl.invoke(NativeMethodAccessorImpl.java:77)
at java.base/jdk.internal.reflect.DelegatingMethodAccessorImpl.invoke(DelegatingMethodAccessorImpl.java:43)
at java.base/java.lang.reflect.Method.invoke(Method.java:568)
at org.testng.internal.invokers.MethodInvocationHelper.invokeMethod(MethodInvocationHelper.java:139)
at org.testng.internal.invokers.TestInvoker.invokeMethod(TestInvoker.java:664)
at org.testng.internal.invokers.TestInvoker.invokeTestMethod(TestInvoker.java:228)
at org.testng.internal.invokers.MethodRunner.runInSequence(MethodRunner.java:63)
at org.testng.internal.invokers.TestInvoker$MethodInvocationAgent.invoke(TestInvoker.java:961)
at org.testng.internal.invokers.TestInvoker.invokeTestMethods(TestInvoker.java:201)
at org.testng.internal.invokers.TestMethodWorker.invokeTestMethods(TestMethodWorker.java:148)
at org.testng.internal.invokers.TestMethodWorker.run(TestMethodWorker.java:128)
at java.base/java.util.concurrent.Executors$RunnableAdapter.call(Executors.java:539)
at java.base/java.util.concurrent.FutureTask.run(FutureTask.java:264)
at org.testng.internal.thread.graph.TestNGFutureTask.run(TestNGFutureTask.java:22)
at java.base/java.util.concurrent.ThreadPoolExecutor.runWorker(ThreadPoolExecutor.java:1136)
at java.base/java.util.concurrent.ThreadPoolExecutor$Worker.run(ThreadPoolExecutor.java:635)
at java.base/java.lang.Thread.run(Thread.java:840)
]]>
    </failure>
  </testcase> <!-- unitSinOfInfinityTest -->
  <testcase classname="org.rntgroup.CalcUnitTests.SinTest" name="unitSinTest" time="0.000"/>
  <testcase classname="org.rntgroup.CalcUnitTests.SinTest" name="unitSinTest" time="0.000">
    <failure message="Result is not correct! expected [0.0] but found [-2.4492935982947064E-16]" type="java.lang.AssertionError">
      <![CDATA[java.lang.AssertionError: Result is not correct! expected [0.0] but found [-2.4492935982947064E-16]
at org.testng.Assert.fail(Assert.java:111)
at org.testng.Assert.failNotEquals(Assert.java:1578)
at org.testng.Assert.assertEquals(Assert.java:728)
at org.rntgroup.CalcUnitTests.SinTest.unitSinTest(SinTest.java:31)
at java.base/jdk.internal.reflect.NativeMethodAccessorImpl.invoke0(Native Method)
at java.base/jdk.internal.reflect.NativeMethodAccessorImpl.invoke(NativeMethodAccessorImpl.java:77)
at java.base/jdk.internal.reflect.DelegatingMethodAccessorImpl.invoke(DelegatingMethodAccessorImpl.java:43)
at java.base/java.lang.reflect.Method.invoke(Method.java:568)
at org.testng.internal.invokers.MethodInvocationHelper.invokeMethod(MethodInvocationHelper.java:139)
at org.testng.internal.invokers.TestInvoker.invokeMethod(TestInvoker.java:664)
at org.testng.internal.invokers.TestInvoker.invokeTestMethod(TestInvoker.java:228)
at org.testng.internal.invokers.MethodRunner.runInSequence(MethodRunner.java:63)
at org.testng.internal.invokers.TestInvoker$MethodInvocationAgent.invoke(TestInvoker.java:961)
at org.testng.internal.invokers.TestInvoker.invokeTestMethods(TestInvoker.java:201)
at org.testng.internal.invokers.TestMethodWorker.invokeTestMethods(TestMethodWorker.java:148)
at org.testng.internal.invokers.TestMethodWorker.run(TestMethodWorker.java:128)
at java.base/java.util.concurrent.Executors$RunnableAdapter.call(Executors.java:539)
at java.base/java.util.concurrent.FutureTask.run(FutureTask.java:264)
at org.testng.internal.thread.graph.TestNGFutureTask.run(TestNGFutureTask.java:22)
at java.base/java.util.concurrent.ThreadPoolExecutor.runWorker(ThreadPoolExecutor.java:1136)
at java.base/java.util.concurrent.ThreadPoolExecutor$Worker.run(ThreadPoolExecutor.java:635)
at java.base/java.lang.Thread.run(Thread.java:840)
]]>
    </failure>
  </testcase> <!-- unitSinTest -->
  <testcase classname="org.rntgroup.CalcUnitTests.SinTest" name="unitSinTest" time="0.000"/>
  <testcase classname="org.rntgroup.CalcUnitTests.SinTest" name="unitSinTest" time="0.001"/>
  <testcase classname="org.rntgroup.CalcUnitTests.SinTest" name="unitSinTest" time="0.000"/>
  <testcase classname="org.rntgroup.CalcUnitTests.SinTest" name="unitSinTest" time="0.001"/>
  <testcase classname="org.rntgroup.CalcUnitTests.SinTest" name="unitSinTest" time="0.000"/>
  <testcase classname="org.rntgroup.CalcUnitTests.SinTest" name="unitSinTest" time="0.001"/>
  <testcase classname="org.rntgroup.CalcUnitTests.SinTest" name="unitSinTest" time="0.001"/>
</testsuite> <!-- org.rntgroup.CalcUnitTests.SinTest -->
